Workbook
Name Days_In_Year: Assumptions!$C$12
Name Min_Cash: Assumptions!$C$13
Name Model_Checks_OK: Checks!$C$19
Name Revolver_Limit: Assumptions!$C$14
Name Scenario: Assumptions!$C$7
Name Scenario_Idx: Assumptions!$C$8
Name Tolerance: Assumptions!$C$15

Sheet Cover
B2: Northwind Components Inc.
B3: Integrated three-statement financial model: income statement, balance sheet, cash flow
B4: FICTIONAL COMPANY. All figures are illustrative; this company and its numbers do not exist.
B5: Built by Adham Karim | github.com/adhamkarim4815/three-statement-model | v1.0.0
B7: Model status
B8: Active scenario | C8: =Scenario -> Base
B9: Model checks | C9: =IF(Model_Checks_OK,"ALL CHECKS PASS","CHECK ERRORS: see Checks sheet") -> ALL CHECKS PASS
B10: Units | C10: $ in millions except per share data. Fiscal year ends December 31.
B11: Timeline | C11: 3 actual years (FY2023A to FY2025A) and 5 forecast years (FY2026E to FY2030E). Same column = same year on every sheet.
B13: How to use
B14: 1. Pick a scenario | C14: Use the dropdown in Assumptions!C7 (named range Scenario): Base, Upside or Downside. Everything recalculates, including the charts.
B15: 2. Change drivers | C15: Edit blue cells on the Assumptions sheet. Each scenario driver has a live row (CHOOSE on the scenario index) above Base, Upside and Downside input rows.
B16: 3. Read the output | C16: Summary shows ratios and charts. Statements and Schedules show the full build. Checks must read ALL CHECKS PASS.
B17: 4. Sensitivity | C17: The Sensitivity sheet is a static, Python-generated table. It does not update with the dropdown.
B19: Sheet guide (click to navigate)
B20: Summary | C20: Dashboard: key lines, ratios (margins, ROE, ROIC, leverage, coverage, FCF), 3 charts
B21: Assumptions | C21: Scenario dropdown and every driver (Base, Upside, Downside); history shown for context
B22: Income Statement | C22: Segment revenue build through net income and per-share data
B23: Balance Sheet | C23: Assets, liabilities and equity; links to schedules; balance check
B24: Cash Flow | C24: Operating, investing and financing cash flows; ending cash feeds the balance sheet
B25: Schedules | C25: PP&E roll-forward, working capital days, term loan, revolver, interest, equity, shares
B26: Checks | C26: Balance, cash tie-out, roll-forwards and debt-limit tests with TRUE/FALSE status
B27: Sensitivity | C27: Python-generated two-way sensitivity of FY2030E EBITDA and FCF (static values)
B29: Colour code
B30: 1234.5 | C30: Blue: hard-coded input or historical data point. Change these.
B31: 1234.5 | C31: Black: formula that calculates from cells on the same sheet.
B32: 1234.5 | C32: Green: formula that pulls from another sheet or from a named input.
B33: 1234.5 | C33: Grey fill: static values generated by Python (Sensitivity sheet only).
B34: Yellow cell | C34: The scenario selector.
B36: Conventions
B37: Signs | C37: Income statement expenses are positive and subtracted. Cash flow outflows are negative.
B38: Interest | C38: Opening-balance basis: no circular references, so Excel never needs iterative calculation. The Python engine can also run an average-balance basis (iterative).
B39: Revolver | C39: Draws to keep cash at or above the minimum cash input, repays from any excess, never goes negative and is capped at the commitment.
B40: Named ranges | C40: Scenario, Scenario_Idx, Days_In_Year, Min_Cash, Revolver_Limit, Tolerance, Model_Checks_OK.
B41: Validation | C41: The test suite recalculates this workbook in LibreOffice and reconciles every line to the Python engine in all three scenarios.
B43: Limitations
B44: Simplified model | C44: Fictional company; simplified cash taxes (no deferred taxes or loss carry-forwards); no leases; goodwill and other long-term liabilities held flat; no FX; one term loan and one revolver; historical cash flows not presented.

Sheet Summary
A1: Northwind Components Inc. (fictional) | Summary dashboard
A2: Key financials, credit statistics and returns. $ in millions except per share data; fiscal year ends December 31.
A3: ="Scenario: "&Scenario -> Scenario: Base
C4: Actual | F4: Forecast
A5: ($ in millions) | B5: Unit | C5: ="FY"&Assumptions!C$5&"A" -> FY2023A | D5: ="FY"&Assumptions!D$5&"A" -> FY2024A | E5: ="FY"&Assumptions!E$5&"A" -> FY2025A | F5: ="FY"&Assumptions!F$5&"E" -> FY2026E | G5: ="FY"&Assumptions!G$5&"E" -> FY2027E | H5: ="FY"&Assumptions!H$5&"E" -> FY2028E | I5: ="FY"&Assumptions!I$5&"E" -> FY2029E | J5: ="FY"&Assumptions!J$5&"E" -> FY2030E
A6: Income statement
A7: Revenue | B7: $m | C7: ='Income Statement'!C10 -> 683 | D7: ='Income Statement'!D10 -> 743.8 | E7: ='Income Statement'!E10 -> 810.7 | F7: ='Income Statement'!F10 -> 871.889 | G7: ='Income Statement'!G10 -> 934.20943 | H7: ='Income Statement'!H10 -> 996.42574 | I7: ='Income Statement'!I10 -> 1055.9367 | J7: ='Income Statement'!J10 -> 1111.6778
A8: % growth | B8: % | D8: ='Income Statement'!D11 -> 0.089019034 | E8: ='Income Statement'!E11 -> 0.089943533 | F8: ='Income Statement'!F11 -> 0.075476748 | G8: ='Income Statement'!G11 -> 0.071477482 | H8: ='Income Statement'!H11 -> 0.066597816 | I8: ='Income Statement'!I11 -> 0.059724404 | J8: ='Income Statement'!J11 -> 0.052788329
A9: Gross profit | B9: $m | C9: ='Income Statement'!C14 -> 245.9 | D9: ='Income Statement'!D14 -> 271.5 | E9: ='Income Statement'!E14 -> 300 | F9: ='Income Statement'!F14 -> 325.2146 | G9: ='Income Statement'!G14 -> 350.32854 | H9: ='Income Statement'!H14 -> 376.64893 | I9: ='Income Statement'!I14 -> 401.25593 | J9: ='Income Statement'!J14 -> 422.43757
A10: % margin | B10: % | C10: ='Income Statement'!C15 -> 0.36002928 | D10: ='Income Statement'!D15 -> 0.36501748 | E10: ='Income Statement'!E15 -> 0.37005057 | F10: ='Income Statement'!F15 -> 0.373 | G10: ='Income Statement'!G15 -> 0.375 | H10: ='Income Statement'!H15 -> 0.378 | I10: ='Income Statement'!I15 -> 0.38 | J10: ='Income Statement'!J15 -> 0.38
A11: EBITDA | B11: $m | C11: ='Income Statement'!C18 -> 112.7 | D11: ='Income Statement'!D18 -> 127.9 | E11: ='Income Statement'!E18 -> 144.4 | F11: ='Income Statement'!F18 -> 158.6838 | G11: ='Income Statement'!G18 -> 172.82874 | H11: ='Income Statement'!H18 -> 188.32446 | I11: ='Income Statement'!I18 -> 202.73984 | J11: ='Income Statement'!J18 -> 214.55382
A12: % margin | B12: % | C12: ='Income Statement'!C19 -> 0.16500732 | D12: ='Income Statement'!D19 -> 0.17195483 | E12: ='Income Statement'!E19 -> 0.17811768 | F12: ='Income Statement'!F19 -> 0.182 | G12: ='Income Statement'!G19 -> 0.185 | H12: ='Income Statement'!H19 -> 0.189 | I12: ='Income Statement'!I19 -> 0.192 | J12: ='Income Statement'!J19 -> 0.193
A13: EBIT margin | B13: % | C13: ='Income Statement'!C22 -> 0.12035139 | D13: ='Income Statement'!D22 -> 0.12785695 | E13: ='Income Statement'!E22 -> 0.13445171 | F13: ='Income Statement'!F22 -> 0.13909316 | G13: ='Income Statement'!G22 -> 0.14196564 | H13: ='Income Statement'!H22 -> 0.14593843 | I13: ='Income Statement'!I22 -> 0.14904766 | J13: ='Income Statement'!J22 -> 0.15012885
A14: Net income | B14: $m | C14: ='Income Statement'!C27 -> 52.1 | D14: ='Income Statement'!D27 -> 62.6 | E14: ='Income Statement'!E27 -> 73.9 | F14: ='Income Statement'!F27 -> 83.504099 | G14: ='Income Statement'!G27 -> 92.900984 | H14: ='Income Statement'!H27 -> 103.41118 | I14: ='Income Statement'!I27 -> 113.43296 | J14: ='Income Statement'!J27 -> 121.97109
A15: % margin | B15: % | C15: ='Income Statement'!C28 -> 0.076281113 | D15: ='Income Statement'!D28 -> 0.084162409 | E15: ='Income Statement'!E28 -> 0.091155791 | F15: ='Income Statement'!F28 -> 0.095773772 | G15: ='Income Statement'!G28 -> 0.099443423 | H15: ='Income Statement'!H28 -> 0.10378213 | I15: ='Income Statement'!I28 -> 0.10742402 | J15: ='Income Statement'!J28 -> 0.10971803
A16: Earnings per share | B16: $ | C16: ='Income Statement'!C33 -> 1.2464115 | D16: ='Income Statement'!D33 -> 1.5231144 | E16: ='Income Statement'!E33 -> 1.8292079 | F16: ='Income Statement'!F33 -> 2.1111646 | G16: ='Income Statement'!G33 -> 2.4015715 | H16: ='Income Statement'!H33 -> 2.7316654 | I16: ='Income Statement'!I33 -> 3.0664441 | J16: ='Income Statement'!J33 -> 3.3797323
A18: Cash flow
A19: Cash flow from operations | B19: $m | F19: ='Cash Flow'!F14 -> 111.31752 | G19: ='Cash Flow'!G14 -> 124.94259 | H19: ='Cash Flow'!H14 -> 136.76467 | I19: ='Cash Flow'!I14 -> 152.8488 | J19: ='Cash Flow'!J14 -> 162.59315
A20: Capital expenditures | B20: $m | F20: ='Cash Flow'!F17 -> -56.672785 | G20: ='Cash Flow'!G17 -> -58.855194 | H20: ='Cash Flow'!H17 -> -59.785544 | I20: ='Cash Flow'!I17 -> -61.244327 | J20: ='Cash Flow'!J17 -> -61.142279
A21: Free cash flow | B21: $m | F21: ='Cash Flow'!F32 -> 54.644732 | G21: ='Cash Flow'!G32 -> 66.087392 | H21: ='Cash Flow'!H32 -> 76.979121 | I21: ='Cash Flow'!I32 -> 91.604473 | J21: ='Cash Flow'!J32 -> 101.45087
A22: FCF margin (% of revenue) | B22: % | F22: =F21/'Income Statement'!F10 -> 0.062673955 | G22: =G21/'Income Statement'!G10 -> 0.070741517 | H22: =H21/'Income Statement'!H10 -> 0.077255252 | I22: =I21/'Income Statement'!I10 -> 0.086751862 | J22: =J21/'Income Statement'!J10 -> 0.091259239
A23: FCF conversion (% of EBITDA) | B23: % | F23: =F21/F11 -> 0.34436239 | G23: =G21/G11 -> 0.38238658 | H23: =H21/H11 -> 0.40875795 | I23: =I21/I11 -> 0.45183262 | J23: =J21/J11 -> 0.4728458
A25: Balance sheet and credit
A26: Cash and equivalents | B26: $m | C26: ='Balance Sheet'!C7 -> 118.2 | D26: ='Balance Sheet'!D7 -> 92.6 | E26: ='Balance Sheet'!E7 -> 88.6 | F26: ='Balance Sheet'!F7 -> 68.193502 | G26: ='Balance Sheet'!G7 -> 60 | H26: ='Balance Sheet'!H7 -> 60 | I26: ='Balance Sheet'!I7 -> 60 | J26: ='Balance Sheet'!J7 -> 64.800492
A27: Total debt | B27: $m | C27: =Schedules!C44 -> 225 | D27: =Schedules!D44 -> 195 | E27: =Schedules!E44 -> 180 | F27: =Schedules!F44 -> 155 | G27: =Schedules!G44 -> 133.5894 | H27: =Schedules!H44 -> 112.63363 | I27: =Schedules!I44 -> 85.05905 | J27: =Schedules!J44 -> 55
A28: Net debt | B28: $m | C28: =Schedules!C45 -> 106.8 | D28: =Schedules!D45 -> 102.4 | E28: =Schedules!E45 -> 91.4 | F28: =Schedules!F45 -> 86.806498 | G28: =Schedules!G45 -> 73.589401 | H28: =Schedules!H45 -> 52.633634 | I28: =Schedules!I45 -> 25.05905 | J28: =Schedules!J45 -> -9.8004925
A29: Net debt / EBITDA | B29: x | C29: =C28/C11 -> 0.94764862 | D29: =D28/D11 -> 0.80062549 | E29: =E28/E11 -> 0.63296399 | F29: =F28/F11 -> 0.54704071 | G29: =G28/G11 -> 0.42579376 | H29: =H28/H11 -> 0.27948378 | I29: =I28/I11 -> 0.123602 | J29: =J28/J11 -> -0.045678481
A30: Interest coverage (EBIT / interest expense) | B30: x | C30: =IF('Income Statement'!C23>0,'Income Statement'!C21/'Income Statement'!C23,"n.m.") -> 5.630137 | D30: =IF('Income Statement'!D23>0,'Income Statement'!D21/'Income Statement'!D23,"n.m.") -> 6.8417266 | E30: =IF('Income Statement'!E23>0,'Income Statement'!E21/'Income Statement'!E23,"n.m.") -> 8.3206107 | F30: =IF('Income Statement'!F23>0,'Income Statement'!F21/'Income Statement'!F23,"n.m.") -> 9.9813826 | G30: =IF('Income Statement'!G23>0,'Income Statement'!G21/'Income Statement'!G23,"n.m.") -> 12.676286 | H30: =IF('Income Statement'!H23>0,'Income Statement'!H21/'Income Statement'!H23,"n.m.") -> 16.09442 | I30: =IF('Income Statement'!I23>0,'Income Statement'!I21/'Income Statement'!I23,"n.m.") -> 20.597586 | J30: =IF('Income Statement'!J23>0,'Income Statement'!J21/'Income Statement'!J23,"n.m.") -> 28.940739
A31: Invested capital (debt + equity - cash) | B31: $m | C31: =C27+'Balance Sheet'!C28-C26 -> 446.8 | D31: =D27+'Balance Sheet'!D28-D26 -> 471.2 | E31: =E27+'Balance Sheet'!E28-E26 -> 496.9 | F31: =F27+'Balance Sheet'!F28-F26 -> 525.75937 | G31: =G27+'Balance Sheet'!G28-G26 -> 552.57296 | H31: =H27+'Balance Sheet'!H28-H26 -> 579.00502 | I31: =I27+'Balance Sheet'!I28-I26 -> 600.83351 | J31: =J27+'Balance Sheet'!J28-J26 -> 621.35373
A33: Returns (on average balances)
A34: Return on equity | B34: % | D34: ='Income Statement'!D27/AVERAGE('Balance Sheet'!C28,'Balance Sheet'!D28) -> 0.17663657 | E34: ='Income Statement'!E27/AVERAGE('Balance Sheet'!D28,'Balance Sheet'!E28) -> 0.19088209 | F34: ='Income Statement'!F27/AVERAGE('Balance Sheet'!E28,'Balance Sheet'!F28) -> 0.19777089 | G34: ='Income Statement'!G27/AVERAGE('Balance Sheet'!F28,'Balance Sheet'!G28) -> 0.20241267 | H34: ='Income Statement'!H27/AVERAGE('Balance Sheet'!G28,'Balance Sheet'!H28) -> 0.20572074 | I34: ='Income Statement'!I27/AVERAGE('Balance Sheet'!H28,'Balance Sheet'!I28) -> 0.20584021 | J34: ='Income Statement'!J27/AVERAGE('Balance Sheet'!I28,'Balance Sheet'!J28) -> 0.20211815
A35: Return on invested capital (NOPAT / invested capital) | B35: % | D35: ='Income Statement'!D21*(1-'Income Statement'!D29)/AVERAGE(C31,D31) -> 0.15533012 | E35: ='Income Statement'!E21*(1-'Income Statement'!E29)/AVERAGE(D31,E31) -> 0.16894466 | F35: ='Income Statement'!F21*(1-'Income Statement'!F29)/AVERAGE(E31,F31) -> 0.17788005 | G35: ='Income Statement'!G21*(1-'Income Statement'!G29)/AVERAGE(F31,G31) -> 0.18448715 | H35: ='Income Statement'!H21*(1-'Income Statement'!H29)/AVERAGE(G31,H31) -> 0.19276198 | I35: ='Income Statement'!I21*(1-'Income Statement'!I29)/AVERAGE(H31,I31) -> 0.20009292 | J35: ='Income Statement'!J21*(1-'Income Statement'!J29)/AVERAGE(I31,J31) -> 0.20483143

Sheet Assumptions
A1: Northwind Components Inc. (fictional) | Assumptions
A2: All inputs live here. Blue cells are hard-coded inputs. $ in millions except per share data; fiscal year ends December 31.
A3: ="Scenario: "&Scenario -> Scenario: Base
C4: Actual | F4: Forecast
A5: ($ in millions) | B5: Unit | C5: 2023 | D5: =C5+1 -> 2024 | E5: =D5+1 -> 2025 | F5: =E5+1 -> 2026 | G5: =F5+1 -> 2027 | H5: =G5+1 -> 2028 | I5: =H5+1 -> 2029 | J5: =I5+1 -> 2030 | K5: Notes
A6: Model controls
A7: Active scenario (choose from list) | B7: list | C7: Base | K7: Single dropdown: every sheet, chart and ratio recalculates.
A8: Scenario index | B8: # | C8: =MATCH(C7,C9:C11,0) -> 1 | K8: Position of the active scenario in the list below; drives CHOOSE().
A9: Scenario list (1) | C9: Base
A10: Scenario list (2) | C10: Upside
A11: Scenario list (3) | C11: Downside
A12: Days in year (working capital) | B12: days | C12: 365
A13: Minimum cash balance | B13: $m | C13: 60 | K13: The revolver draws to defend this level and repays from any excess.
A14: Revolver commitment | B14: $m | C14: 150
A15: Check tolerance | B15: $m | C15: 0.001
A16: Interest basis: opening balances (no circular references). The Python engine also offers an average-balance mode solved iteratively.
A18: Scenario drivers (first row of each block is live; edit the three rows beneath)
A19: Revenue growth: Industrial Controls | B19: % | D19: ='Income Statement'!D7/'Income Statement'!C7-1 -> 0.072580645 | E19: ='Income Statement'!E7/'Income Statement'!D7-1 -> 0.073082707 | F19: =CHOOSE(Scenario_Idx,F20,F21,F22) -> 0.065 | G19: =CHOOSE(Scenario_Idx,G20,G21,G22) -> 0.06 | H19: =CHOOSE(Scenario_Idx,H20,H21,H22) -> 0.055 | I19: =CHOOSE(Scenario_Idx,I20,I21,I22) -> 0.05 | J19: =CHOOSE(Scenario_Idx,J20,J21,J22) -> 0.045 | K19: Year-over-year growth for the segment.
A20: Base | B20: % | F20: 0.065 | G20: 0.06 | H20: 0.055 | I20: 0.05 | J20: 0.045
A21: Upside | B21: % | F21: 0.085 | G21: 0.08 | H21: 0.075 | I21: 0.07 | J21: 0.06
A22: Downside | B22: % | F22: -0.02 | G22: 0.005 | H22: 0.025 | I22: 0.035 | J22: 0.04
A23: Revenue growth: Automotive Sensors | B23: % | D23: ='Income Statement'!D8/'Income Statement'!C8-1 -> 0.10352941 | E23: ='Income Statement'!E8/'Income Statement'!D8-1 -> 0.10589908 | F23: =CHOOSE(Scenario_Idx,F24,F25,F26) -> 0.09 | G23: =CHOOSE(Scenario_Idx,G24,G25,G26) -> 0.085 | H23: =CHOOSE(Scenario_Idx,H24,H25,H26) -> 0.08 | I23: =CHOOSE(Scenario_Idx,I24,I25,I26) -> 0.07 | J23: =CHOOSE(Scenario_Idx,J24,J25,J26) -> 0.06 | K23: Year-over-year growth for the segment.
A24: Base | B24: % | F24: 0.09 | G24: 0.085 | H24: 0.08 | I24: 0.07 | J24: 0.06
A25: Upside | B25: % | F25: 0.12 | G25: 0.11 | H25: 0.1 | I25: 0.09 | J25: 0.08
A26: Downside | B26: % | F26: -0.06 | G26: -0.01 | H26: 0.03 | I26: 0.05 | J26: 0.055
A27: Revenue growth: Aftermarket Services | B27: % | D27: ='Income Statement'!D9/'Income Statement'!C9-1 -> 0.10084746 | E27: ='Income Statement'!E9/'Income Statement'!D9-1 -> 0.098537336 | F27: =CHOOSE(Scenario_Idx,F28,F29,F30) -> 0.07 | G27: =CHOOSE(Scenario_Idx,G28,G29,G30) -> 0.07 | H27: =CHOOSE(Scenario_Idx,H28,H29,H30) -> 0.065 | I27: =CHOOSE(Scenario_Idx,I28,I29,I30) -> 0.06 | J27: =CHOOSE(Scenario_Idx,J28,J29,J30) -> 0.055 | K27: Year-over-year growth for the segment.
A28: Base | B28: % | F28: 0.07 | G28: 0.07 | H28: 0.065 | I28: 0.06 | J28: 0.055
A29: Upside | B29: % | F29: 0.09 | G29: 0.09 | H29: 0.085 | I29: 0.08 | J29: 0.07
A30: Downside | B30: % | F30: 0.01 | G30: 0.02 | H30: 0.03 | I30: 0.035 | J30: 0.04
A31: Gross margin (before D&A) | B31: % | C31: ='Income Statement'!C15 -> 0.36002928 | D31: ='Income Statement'!D15 -> 0.36501748 | E31: ='Income Statement'!E15 -> 0.37005057 | F31: =CHOOSE(Scenario_Idx,F32,F33,F34) -> 0.373 | G31: =CHOOSE(Scenario_Idx,G32,G33,G34) -> 0.375 | H31: =CHOOSE(Scenario_Idx,H32,H33,H34) -> 0.378 | I31: =CHOOSE(Scenario_Idx,I32,I33,I34) -> 0.38 | J31: =CHOOSE(Scenario_Idx,J32,J33,J34) -> 0.38 | K31: COGS excludes depreciation and amortization.
A32: Base | B32: % | F32: 0.373 | G32: 0.375 | H32: 0.378 | I32: 0.38 | J32: 0.38
A33: Upside | B33: % | F33: 0.378 | G33: 0.384 | H33: 0.389 | I33: 0.393 | J33: 0.395
A34: Downside | B34: % | F34: 0.355 | G34: 0.353 | H34: 0.358 | I34: 0.363 | J34: 0.365
A35: SG&A as % of revenue | B35: % | C35: ='Income Statement'!C16/'Income Statement'!C10 -> 0.14494876 | D35: ='Income Statement'!D16/'Income Statement'!D10 -> 0.14304921 | E35: ='Income Statement'!E16/'Income Statement'!E10 -> 0.14098927 | F35: =CHOOSE(Scenario_Idx,F36,F37,F38) -> 0.14 | G35: =CHOOSE(Scenario_Idx,G36,G37,G38) -> 0.139 | H35: =CHOOSE(Scenario_Idx,H36,H37,H38) -> 0.138 | I35: =CHOOSE(Scenario_Idx,I36,I37,I38) -> 0.137 | J35: =CHOOSE(Scenario_Idx,J36,J37,J38) -> 0.136 | K35: Downside deleverages: fixed costs do not flex with revenue.
A36: Base | B36: % | F36: 0.14 | G36: 0.139 | H36: 0.138 | I36: 0.137 | J36: 0.136
A37: Upside | B37: % | F37: 0.138 | G37: 0.136 | H37: 0.134 | I37: 0.132 | J37: 0.131
A38: Downside | B38: % | F38: 0.148 | G38: 0.149 | H38: 0.146 | I38: 0.143 | J38: 0.141
A39: Capex as % of revenue | B39: % | D39: =Schedules!D8/'Income Statement'!D10 -> 0.064667921 | E39: =Schedules!E8/'Income Statement'!E10 -> 0.06426545 | F39: =CHOOSE(Scenario_Idx,F40,F41,F42) -> 0.065 | G39: =CHOOSE(Scenario_Idx,G40,G41,G42) -> 0.063 | H39: =CHOOSE(Scenario_Idx,H40,H41,H42) -> 0.06 | I39: =CHOOSE(Scenario_Idx,I40,I41,I42) -> 0.058 | J39: =CHOOSE(Scenario_Idx,J40,J41,J42) -> 0.055 | K39: Historical capex is implied from the PP&E roll-forward.
A40: Base | B40: % | F40: 0.065 | G40: 0.063 | H40: 0.06 | I40: 0.058 | J40: 0.055
A41: Upside | B41: % | F41: 0.068 | G41: 0.066 | H41: 0.063 | I41: 0.06 | J41: 0.058
...

Sheet Income Statement
A1: Northwind Components Inc. (fictional) | Income statement
A2: Revenue build, margins and earnings. $ in millions except per share data; fiscal year ends December 31.
A3: ="Scenario: "&Scenario -> Scenario: Base
C4: Actual | F4: Forecast
A5: ($ in millions) | B5: Unit | C5: =Assumptions!C$5 -> 2023 | D5: =Assumptions!D$5 -> 2024 | E5: =Assumptions!E$5 -> 2025 | F5: =Assumptions!F$5 -> 2026 | G5: =Assumptions!G$5 -> 2027 | H5: =Assumptions!H$5 -> 2028 | I5: =Assumptions!I$5 -> 2029 | J5: =Assumptions!J$5 -> 2030
A6: Revenue
A7: Industrial Controls | B7: $m | C7: 310 | D7: 332.5 | E7: 356.8 | F7: =E7*(1+Assumptions!F19) -> 379.992 | G7: =F7*(1+Assumptions!G19) -> 402.79152 | H7: =G7*(1+Assumptions!H19) -> 424.94505 | I7: =H7*(1+Assumptions!I19) -> 446.19231 | J7: =I7*(1+Assumptions!J19) -> 466.27096
A8: Automotive Sensors | B8: $m | C8: 255 | D8: 281.4 | E8: 311.2 | F8: =E8*(1+Assumptions!F23) -> 339.208 | G8: =F8*(1+Assumptions!G23) -> 368.04068 | H8: =G8*(1+Assumptions!H23) -> 397.48393 | I8: =H8*(1+Assumptions!I23) -> 425.30781 | J8: =I8*(1+Assumptions!J23) -> 450.82628
A9: Aftermarket Services | B9: $m | C9: 118 | D9: 129.9 | E9: 142.7 | F9: =E9*(1+Assumptions!F27) -> 152.689 | G9: =F9*(1+Assumptions!G27) -> 163.37723 | H9: =G9*(1+Assumptions!H27) -> 173.99675 | I9: =H9*(1+Assumptions!I27) -> 184.43655 | J9: =I9*(1+Assumptions!J27) -> 194.58057
A10: Total revenue | B10: $m | C10: =SUM(C7:C9) -> 683 | D10: =SUM(D7:D9) -> 743.8 | E10: =SUM(E7:E9) -> 810.7 | F10: =SUM(F7:F9) -> 871.889 | G10: =SUM(G7:G9) -> 934.20943 | H10: =SUM(H7:H9) -> 996.42574 | I10: =SUM(I7:I9) -> 1055.9367 | J10: =SUM(J7:J9) -> 1111.6778
A11: % growth | B11: % | D11: =D10/C10-1 -> 0.089019034 | E11: =E10/D10-1 -> 0.089943533 | F11: =F10/E10-1 -> 0.075476748 | G11: =G10/F10-1 -> 0.071477482 | H11: =H10/G10-1 -> 0.066597816 | I11: =I10/H10-1 -> 0.059724404 | J11: =J10/I10-1 -> 0.052788329
A13: Cost of goods sold (excl. D&A) | B13: $m | C13: 437.1 | D13: 472.3 | E13: 510.7 | F13: =F10*(1-Assumptions!F31) -> 546.6744 | G13: =G10*(1-Assumptions!G31) -> 583.88089 | H13: =H10*(1-Assumptions!H31) -> 619.77681 | I13: =I10*(1-Assumptions!I31) -> 654.68074 | J13: =J10*(1-Assumptions!J31) -> 689.24024
A14: Gross profit | B14: $m | C14: =C10-C13 -> 245.9 | D14: =D10-D13 -> 271.5 | E14: =E10-E13 -> 300 | F14: =F10-F13 -> 325.2146 | G14: =G10-G13 -> 350.32854 | H14: =H10-H13 -> 376.64893 | I14: =I10-I13 -> 401.25593 | J14: =J10-J13 -> 422.43757
A15: % margin | B15: % | C15: =C14/C10 -> 0.36002928 | D15: =D14/D10 -> 0.36501748 | E15: =E14/E10 -> 0.37005057 | F15: =F14/F10 -> 0.373 | G15: =G14/G10 -> 0.375 | H15: =H14/H10 -> 0.378 | I15: =I14/I10 -> 0.38 | J15: =J14/J10 -> 0.38
A16: Selling, general and administrative | B16: $m | C16: 99 | D16: 106.4 | E16: 114.3 | F16: =F10*Assumptions!F35 -> 122.06446 | G16: =G10*Assumptions!G35 -> 129.85511 | H16: =H10*Assumptions!H35 -> 137.50675 | I16: =I10*Assumptions!I35 -> 144.66332 | J16: =J10*Assumptions!J35 -> 151.18818
A17: Research and development | B17: $m | C17: 34.2 | D17: 37.2 | E17: 41.3 | F17: =F10*Assumptions!F53 -> 44.466339 | G17: =G10*Assumptions!G53 -> 47.644681 | H17: =H10*Assumptions!H53 -> 50.817713 | I17: =I10*Assumptions!I53 -> 53.85277 | J17: =J10*Assumptions!J53 -> 56.695568
A18: EBITDA | B18: $m | C18: =C14-C16-C17 -> 112.7 | D18: =D14-D16-D17 -> 127.9 | E18: =E14-E16-E17 -> 144.4 | F18: =F14-F16-F17 -> 158.6838 | G18: =G14-G16-G17 -> 172.82874 | H18: =H14-H16-H17 -> 188.32446 | I18: =I14-I16-I17 -> 202.73984 | J18: =J14-J16-J17 -> 214.55382
A19: % margin | B19: % | C19: =C18/C10 -> 0.16500732 | D19: =D18/D10 -> 0.17195483 | E19: =E18/E10 -> 0.17811768 | F19: =F18/F10 -> 0.182 | G19: =G18/G10 -> 0.185 | H19: =H18/H10 -> 0.189 | I19: =I18/I10 -> 0.192 | J19: =J18/J10 -> 0.193
A20: Depreciation and amortization | B20: $m | C20: 30.5 | D20: 32.8 | E20: 35.4 | F20: =Schedules!F9 -> 37.41 | G20: =Schedules!G9 -> 40.203104 | H20: =Schedules!H9 -> 42.907657 | I20: =Schedules!I9 -> 45.354951 | J20: =Schedules!J9 -> 47.65891
A21: EBIT (operating income) | B21: $m | C21: =C18-C20 -> 82.2 | D21: =D18-D20 -> 95.1 | E21: =E18-E20 -> 109 | F21: =F18-F20 -> 121.2738 | G21: =G18-G20 -> 132.62564 | H21: =H18-H20 -> 145.41681 | I21: =I18-I20 -> 157.38489 | J21: =J18-J20 -> 166.89491
A22: % margin | B22: % | C22: =C21/C10 -> 0.12035139 | D22: =D21/D10 -> 0.12785695 | E22: =E21/E10 -> 0.13445171 | F22: =F21/F10 -> 0.13909316 | G22: =G21/G10 -> 0.14196564 | H22: =H21/H10 -> 0.14593843 | I22: =I21/I10 -> 0.14904766 | J22: =J21/J10 -> 0.15012885
A23: Interest expense | B23: $m | C23: 14.6 | D23: 13.9 | E23: 13.1 | F23: =Schedules!F50 -> 12.15 | G23: =Schedules!G50 -> 10.4625 | H23: =Schedules!H50 -> 9.0352316 | I23: =Schedules!I50 -> 7.6409385 | J23: =Schedules!J50 -> 5.7667811
A24: Interest income | B24: $m | C24: 1.9 | D24: 2.3 | E24: 2.6 | F24: =Schedules!F51 -> 2.215 | G24: =Schedules!G51 -> 1.7048376 | H24: =Schedules!H51 -> 1.5 | I24: =Schedules!I51 -> 1.5 | J24: =Schedules!J51 -> 1.5
A25: Pre-tax income | B25: $m | C25: =C21-C23+C24 -> 69.5 | D25: =D21-D23+D24 -> 83.5 | E25: =E21-E23+E24 -> 98.5 | F25: =F21-F23+F24 -> 111.3388 | G25: =G21-G23+G24 -> 123.86798 | H25: =H21-H23+H24 -> 137.88158 | I25: =I21-I23+I24 -> 151.24395 | J25: =J21-J23+J24 -> 162.62812
A26: Income tax expense | B26: $m | C26: 17.4 | D26: 20.9 | E26: 24.6 | F26: =MAX(0,F25)*Assumptions!F58 -> 27.8347 | G26: =MAX(0,G25)*Assumptions!G58 -> 30.966995 | H26: =MAX(0,H25)*Assumptions!H58 -> 34.470394 | I26: =MAX(0,I25)*Assumptions!I58 -> 37.810988 | J26: =MAX(0,J25)*Assumptions!J58 -> 40.657031
A27: Net income | B27: $m | C27: =C25-C26 -> 52.1 | D27: =D25-D26 -> 62.6 | E27: =E25-E26 -> 73.9 | F27: =F25-F26 -> 83.504099 | G27: =G25-G26 -> 92.900984 | H27: =H25-H26 -> 103.41118 | I27: =I25-I26 -> 113.43296 | J27: =J25-J26 -> 121.97109
A28: % margin | B28: % | C28: =C27/C10 -> 0.076281113 | D28: =D27/D10 -> 0.084162409 | E28: =E27/E10 -> 0.091155791 | F28: =F27/F10 -> 0.095773772 | G28: =G27/G10 -> 0.099443423 | H28: =H27/H10 -> 0.10378213 | I28: =I27/I10 -> 0.10742402 | J28: =J27/J10 -> 0.10971803
A29: Effective tax rate | B29: % | C29: =IF(C25>0,C26/C25,0) -> 0.25035971 | D29: =IF(D25>0,D26/D25,0) -> 0.2502994 | E29: =IF(E25>0,E26/E25,0) -> 0.24974619 | F29: =IF(F25>0,F26/F25,0) -> 0.25 | G29: =IF(G25>0,G26/G25,0) -> 0.25 | H29: =IF(H25>0,H26/H25,0) -> 0.25 | I29: =IF(I25>0,I26/I25,0) -> 0.25 | J29: =IF(J25>0,J26/J25,0) -> 0.25
A31: Per share data
A32: Weighted average shares outstanding | B32: m | C32: =Schedules!C72 -> 41.8 | D32: =Schedules!D72 -> 41.1 | E32: =Schedules!E72 -> 40.4 | F32: =Schedules!F72 -> 39.553571 | G32: =Schedules!G72 -> 38.683414 | H32: =Schedules!H72 -> 37.856459 | I32: =Schedules!I72 -> 36.991695 | J32: =Schedules!J72 -> 36.08898
A33: Earnings per share | B33: $ | C33: =C27/C32 -> 1.2464115 | D33: =D27/D32 -> 1.5231144 | E33: =E27/E32 -> 1.8292079 | F33: =F27/F32 -> 2.1111646 | G33: =G27/G32 -> 2.4015715 | H33: =H27/H32 -> 2.7316654 | I33: =I27/I32 -> 3.0664441 | J33: =J27/J32 -> 3.3797323
A34: Dividends per share | B34: $ | D34: =Schedules!D56/D32 -> 0.45742092 | E34: =Schedules!E56/E32 -> 0.54950495 | F34: =Schedules!F56/F32 -> 0.63334937 | G34: =Schedules!G56/G32 -> 0.72047144 | H34: =Schedules!H56/H32 -> 0.81949963 | I34: =Schedules!I56/I32 -> 0.91993322 | J34: =Schedules!J56/J32 -> 1.0139197

Sheet Balance Sheet
A1: Northwind Components Inc. (fictional) | Balance sheet
A2: Year-end balances. $ in millions except per share data; fiscal year ends December 31.
A3: ="Scenario: "&Scenario -> Scenario: Base
C4: Actual | F4: Forecast
A5: ($ in millions) | B5: Unit | C5: =Assumptions!C$5 -> 2023 | D5: =Assumptions!D$5 -> 2024 | E5: =Assumptions!E$5 -> 2025 | F5: =Assumptions!F$5 -> 2026 | G5: =Assumptions!G$5 -> 2027 | H5: =Assumptions!H$5 -> 2028 | I5: =Assumptions!I$5 -> 2029 | J5: =Assumptions!J$5 -> 2030
A6: Assets
A7: Cash and equivalents | B7: $m | C7: 118.2 | D7: 92.6 | E7: 88.6 | F7: ='Cash Flow'!F30 -> 68.193502 | G7: ='Cash Flow'!G30 -> 60 | H7: ='Cash Flow'!H30 -> 60 | I7: ='Cash Flow'!I30 -> 60 | J7: ='Cash Flow'!J30 -> 64.800492
A8: Accounts receivable | B8: $m | C8: 95.4 | D8: 106 | E8: 115.5 | F8: =Schedules!F13 -> 124.21432 | G8: =Schedules!G13 -> 133.09285 | H8: =Schedules!H13 -> 141.95654 | I8: =Schedules!I13 -> 148.98832 | J8: =Schedules!J13 -> 155.33032
A9: Inventory | B9: $m | C9: 92.2 | D9: 98.3 | E9: 104.9 | F9: =Schedules!F14 -> 112.33036 | G9: =Schedules!G14 -> 118.37585 | H9: =Schedules!H14 -> 125.65338 | I9: =Schedules!I14 -> 130.93615 | J9: =Schedules!J14 -> 137.84805
A10: Prepaid and other current assets | B10: $m | C10: 17.1 | D10: 18.6 | E10: 20.3 | F10: =Schedules!F15 -> 21.797225 | G10: =Schedules!G15 -> 23.355236 | H10: =Schedules!H15 -> 24.910643 | I10: =Schedules!I15 -> 26.398417 | J10: =Schedules!J15 -> 27.791945
A11: Total current assets | B11: $m | C11: =SUM(C7:C10) -> 322.9 | D11: =SUM(D7:D10) -> 315.5 | E11: =SUM(E7:E10) -> 329.3 | F11: =SUM(F7:F10) -> 326.53541 | G11: =SUM(G7:G10) -> 334.82394 | H11: =SUM(H7:H10) -> 352.52057 | I11: =SUM(I7:I10) -> 366.32289 | J11: =SUM(J7:J10) -> 385.77081
A12: Net property, plant and equipment | B12: $m | C12: 226 | D12: 241.3 | E12: 258 | F12: =Schedules!F10 -> 277.26279 | G12: =Schedules!G10 -> 295.91488 | H12: =Schedules!H10 -> 312.79276 | I12: =Schedules!I10 -> 328.68214 | J12: =Schedules!J10 -> 342.16551
A13: Goodwill and intangibles | B13: $m | C13: 140 | D13: 140 | E13: 140 | F13: =E13 -> 140 | G13: =F13 -> 140 | H13: =G13 -> 140 | I13: =H13 -> 140 | J13: =I13 -> 140
A14: Total assets | B14: $m | C14: =C11+C12+C13 -> 688.9 | D14: =D11+D12+D13 -> 696.8 | E14: =E11+E12+E13 -> 727.3 | F14: =F11+F12+F13 -> 743.79819 | G14: =G11+G12+G13 -> 770.73881 | H14: =H11+H12+H13 -> 805.31333 | I14: =I11+I12+I13 -> 835.00503 | J14: =J11+J12+J13 -> 867.93632
A16: Liabilities
A17: Accounts payable | B17: $m | C17: 56.3 | D17: 62.1 | E17: 67.2 | F17: =Schedules!F16 -> 71.891428 | G17: =Schedules!G16 -> 76.784337 | H17: =Schedules!H16 -> 81.504895 | I17: =Schedules!I16 -> 86.095001 | J17: =Schedules!J16 -> 90.639812
A18: Accrued liabilities | B18: $m | C18: 37.6 | D18: 40.9 | E18: 44.6 | F18: =Schedules!F17 -> 47.953895 | G18: =Schedules!G17 -> 51.381519 | H18: =Schedules!H17 -> 54.803416 | I18: =Schedules!I17 -> 58.076517 | J18: =Schedules!J17 -> 61.142279
A19: Revolving credit facility | B19: $m | C19: 15 | D19: 0 | E19: 0 | F19: =Schedules!F41 -> 0 | G19: =Schedules!G41 -> 3.5894008 | H19: =Schedules!H41 -> 7.6336341 | I19: =Schedules!I41 -> 5.0590503 | J19: =Schedules!J41 -> 0
A20: Term loan | B20: $m | C20: 210 | D20: 195 | E20: 180 | F20: =Schedules!F24 -> 155 | G20: =Schedules!G24 -> 130 | H20: =Schedules!H24 -> 105 | I20: =Schedules!I24 -> 80 | J20: =Schedules!J24 -> 55
A21: Other long-term liabilities | B21: $m | C21: 30 | D21: 30 | E21: 30 | F21: =E21 -> 30 | G21: =F21 -> 30 | H21: =G21 -> 30 | I21: =H21 -> 30 | J21: =I21 -> 30
A22: Total liabilities | B22: $m | C22: =SUM(C17:C21) -> 348.9 | D22: =SUM(D17:D21) -> 328 | E22: =SUM(E17:E21) -> 321.8 | F22: =SUM(F17:F21) -> 304.84532 | G22: =SUM(G17:G21) -> 291.75526 | H22: =SUM(H17:H21) -> 278.94195 | I22: =SUM(I17:I21) -> 259.23057 | J22: =SUM(J17:J21) -> 236.78209
A24: Shareholders' equity
A25: Common stock and paid-in capital | B25: $m | C25: 120 | D25: 120 | E25: 120 | F25: =Schedules!F62 -> 125 | G25: =Schedules!G62 -> 130 | H25: =Schedules!H62 -> 135 | I25: =Schedules!I62 -> 140 | J25: =Schedules!J62 -> 145
A26: Retained earnings | B26: $m | C26: 240 | D26: 283.8 | E26: 335.5 | F26: =Schedules!F57 -> 393.95287 | G26: =Schedules!G57 -> 458.98356 | H26: =Schedules!H57 -> 531.37138 | I26: =Schedules!I57 -> 610.77446 | J26: =Schedules!J57 -> 696.15423
A27: Treasury stock | B27: $m | C27: -20 | D27: -35 | E27: -50 | F27: =Schedules!F65 -> -80 | G27: =Schedules!G65 -> -110 | H27: =Schedules!H65 -> -140 | I27: =Schedules!I65 -> -175 | J27: =Schedules!J65 -> -210
A28: Total shareholders' equity | B28: $m | C28: =SUM(C25:C27) -> 340 | D28: =SUM(D25:D27) -> 368.8 | E28: =SUM(E25:E27) -> 405.5 | F28: =SUM(F25:F27) -> 438.95287 | G28: =SUM(G25:G27) -> 478.98356 | H28: =SUM(H25:H27) -> 526.37138 | I28: =SUM(I25:I27) -> 575.77446 | J28: =SUM(J25:J27) -> 631.15423
A29: Total liabilities and equity | B29: $m | C29: =C22+C28 -> 688.9 | D29: =D22+D28 -> 696.8 | E29: =E22+E28 -> 727.3 | F29: =F22+F28 -> 743.79819 | G29: =G22+G28 -> 770.73881 | H29: =H22+H28 -> 805.31333 | I29: =I22+I28 -> 835.00503 | J29: =J22+J28 -> 867.93632
A31: Balance check (assets less liabilities and equity) | B31: $m | C31: =ROUND(C14-C29,6) -> 1.1368684e-13 | D31: =ROUND(D14-D29,6) -> 0 | E31: =ROUND(E14-E29,6) -> 0 | F31: =ROUND(F14-F29,6) -> 0 | G31: =ROUND(G14-G29,6) -> 0 | H31: =ROUND(H14-H29,6) -> 0 | I31: =ROUND(I14-I29,6) -> -1.1368684e-13 | J31: =ROUND(J14-J29,6) -> 0

Sheet Cash Flow
A1: Northwind Components Inc. (fictional) | Cash flow statement
A2: Indirect method. $ in millions except per share data; fiscal year ends December 31.
A3: ="Scenario: "&Scenario -> Scenario: Base
C4: Actual | F4: Forecast
A5: ($ in millions) | B5: Unit | C5: =Assumptions!C$5 -> 2023 | D5: =Assumptions!D$5 -> 2024 | E5: =Assumptions!E$5 -> 2025 | F5: =Assumptions!F$5 -> 2026 | G5: =Assumptions!G$5 -> 2027 | H5: =Assumptions!H$5 -> 2028 | I5: =Assumptions!I$5 -> 2029 | J5: =Assumptions!J$5 -> 2030
A6: Operating activities
A7: Net income | B7: $m | F7: ='Income Statement'!F27 -> 83.504099 | G7: ='Income Statement'!G27 -> 92.900984 | H7: ='Income Statement'!H27 -> 103.41118 | I7: ='Income Statement'!I27 -> 113.43296 | J7: ='Income Statement'!J27 -> 121.97109
A8: Depreciation and amortization | B8: $m | F8: ='Income Statement'!F20 -> 37.41 | G8: ='Income Statement'!G20 -> 40.203104 | H8: ='Income Statement'!H20 -> 42.907657 | I8: ='Income Statement'!I20 -> 45.354951 | J8: ='Income Statement'!J20 -> 47.65891
A9: (Increase) / decrease in accounts receivable | B9: $m | F9: =-('Balance Sheet'!F8-'Balance Sheet'!E8) -> -8.7143233 | G9: =-('Balance Sheet'!G8-'Balance Sheet'!F8) -> -8.878527 | H9: =-('Balance Sheet'!H8-'Balance Sheet'!G8) -> -8.8636932 | I9: =-('Balance Sheet'!I8-'Balance Sheet'!H8) -> -7.0317813 | J9: =-('Balance Sheet'!J8-'Balance Sheet'!I8) -> -6.3419985
A10: (Increase) / decrease in inventory | B10: $m | F10: =-('Balance Sheet'!F9-'Balance Sheet'!E9) -> -7.4303568 | G10: =-('Balance Sheet'!G9-'Balance Sheet'!F9) -> -6.0454957 | H10: =-('Balance Sheet'!H9-'Balance Sheet'!G9) -> -7.277528 | I10: =-('Balance Sheet'!I9-'Balance Sheet'!H9) -> -5.2827668 | J10: =-('Balance Sheet'!J9-'Balance Sheet'!I9) -> -6.9119005
A11: (Increase) / decrease in other current assets | B11: $m | F11: =-('Balance Sheet'!F10-'Balance Sheet'!E10) -> -1.497225 | G11: =-('Balance Sheet'!G10-'Balance Sheet'!F10) -> -1.5580108 | H11: =-('Balance Sheet'!H10-'Balance Sheet'!G10) -> -1.5554077 | I11: =-('Balance Sheet'!I10-'Balance Sheet'!H10) -> -1.4877733 | J11: =-('Balance Sheet'!J10-'Balance Sheet'!I10) -> -1.3935283
A12: Increase / (decrease) in accounts payable | B12: $m | F12: =+('Balance Sheet'!F17-'Balance Sheet'!E17) -> 4.6914283 | G12: =+('Balance Sheet'!G17-'Balance Sheet'!F17) -> 4.8929084 | H12: =+('Balance Sheet'!H17-'Balance Sheet'!G17) -> 4.7205587 | I12: =+('Balance Sheet'!I17-'Balance Sheet'!H17) -> 4.5901055 | J12: =+('Balance Sheet'!J17-'Balance Sheet'!I17) -> 4.5448113
A13: Increase / (decrease) in accrued liabilities | B13: $m | F13: =+('Balance Sheet'!F18-'Balance Sheet'!E18) -> 3.353895 | G13: =+('Balance Sheet'!G18-'Balance Sheet'!F18) -> 3.4276237 | H13: =+('Balance Sheet'!H18-'Balance Sheet'!G18) -> 3.4218969 | I13: =+('Balance Sheet'!I18-'Balance Sheet'!H18) -> 3.2731013 | J13: =+('Balance Sheet'!J18-'Balance Sheet'!I18) -> 3.0657623
A14: Cash flow from operations | B14: $m | F14: =SUM(F7:F13) -> 111.31752 | G14: =SUM(G7:G13) -> 124.94259 | H14: =SUM(H7:H13) -> 136.76467 | I14: =SUM(I7:I13) -> 152.8488 | J14: =SUM(J7:J13) -> 162.59315
A16: Investing activities
A17: Capital expenditures | B17: $m | F17: =-Schedules!F8 -> -56.672785 | G17: =-Schedules!G8 -> -58.855194 | H17: =-Schedules!H8 -> -59.785544 | I17: =-Schedules!I8 -> -61.244327 | J17: =-Schedules!J8 -> -61.142279
A18: Cash flow from investing | B18: $m | F18: =F17 -> -56.672785 | G18: =G17 -> -58.855194 | H18: =H17 -> -59.785544 | I18: =I17 -> -61.244327 | J18: =J17 -> -61.142279
A20: Financing activities
A21: Term loan mandatory amortization | B21: $m | F21: =-Schedules!F23 -> -25 | G21: =-Schedules!G23 -> -25 | H21: =-Schedules!H23 -> -25 | I21: =-Schedules!I23 -> -25 | J21: =-Schedules!J23 -> -25
A22: Revolver draw / (repayment) | B22: $m | F22: =Schedules!F40 -> 0 | G22: =Schedules!G40 -> 3.5894008 | H22: =Schedules!H40 -> 4.0442332 | I22: =Schedules!I40 -> -2.5745837 | J22: =Schedules!J40 -> -5.0590503
A23: Stock issuance | B23: $m | F23: =Schedules!F61 -> 5 | G23: =Schedules!G61 -> 5 | H23: =Schedules!H61 -> 5 | I23: =Schedules!I61 -> 5 | J23: =Schedules!J61 -> 5
A24: Dividends paid | B24: $m | F24: =-Schedules!F56 -> -25.05123 | G24: =-Schedules!G56 -> -27.870295 | H24: =-Schedules!H56 -> -31.023355 | I24: =-Schedules!I56 -> -34.029889 | J24: =-Schedules!J56 -> -36.591328
A25: Share buybacks | B25: $m | F25: =-Schedules!F64 -> -30 | G25: =-Schedules!G64 -> -30 | H25: =-Schedules!H64 -> -30 | I25: =-Schedules!I64 -> -35 | J25: =-Schedules!J64 -> -35
A26: Cash flow from financing | B26: $m | F26: =SUM(F21:F25) -> -75.05123 | G26: =SUM(G21:G25) -> -74.280894 | H26: =SUM(H21:H25) -> -76.979121 | I26: =SUM(I21:I25) -> -91.604473 | J26: =SUM(J21:J25) -> -96.650378
A28: Net change in cash | B28: $m | F28: =F14+F18+F26 -> -20.406498 | G28: =G14+G18+G26 -> -8.1935022 | H28: =H14+H18+H26 -> -1.4210855e-14 | I28: =I14+I18+I26 -> -2.8421709e-14 | J28: =J14+J18+J26 -> 4.8004925
A29: Cash, beginning of year | B29: $m | F29: ='Balance Sheet'!E7 -> 88.6 | G29: ='Balance Sheet'!F7 -> 68.193502 | H29: ='Balance Sheet'!G7 -> 60 | I29: ='Balance Sheet'!H7 -> 60 | J29: ='Balance Sheet'!I7 -> 60
A30: Cash, end of year | B30: $m | F30: =F29+F28 -> 68.193502 | G30: =G29+G28 -> 60 | H30: =H29+H28 -> 60 | I30: =I29+I28 -> 60 | J30: =J29+J28 -> 64.800492
A32: Free cash flow (CFO less capex) | B32: $m | F32: =F14+F17 -> 54.644732 | G32: =G14+G17 -> 66.087392 | H32: =H14+H17 -> 76.979121 | I32: =I14+I17 -> 91.604473 | J32: =J14+J17 -> 101.45087
A33: Historical cash flows are not presented: the model starts from three balance sheets.

Sheet Schedules
A1: Northwind Components Inc. (fictional) | Supporting schedules
A2: PP&E, working capital, debt, interest, equity and shares. $ in millions except per share data; fiscal year ends December 31.
A3: ="Scenario: "&Scenario -> Scenario: Base
C4: Actual | F4: Forecast
A5: ($ in millions) | B5: Unit | C5: =Assumptions!C$5 -> 2023 | D5: =Assumptions!D$5 -> 2024 | E5: =Assumptions!E$5 -> 2025 | F5: =Assumptions!F$5 -> 2026 | G5: =Assumptions!G$5 -> 2027 | H5: =Assumptions!H$5 -> 2028 | I5: =Assumptions!I$5 -> 2029 | J5: =Assumptions!J$5 -> 2030
A6: PP&E roll-forward
A7: Opening net PP&E | B7: $m | D7: =C10 -> 226 | E7: =D10 -> 241.3 | F7: =E10 -> 258 | G7: =F10 -> 277.26279 | H7: =G10 -> 295.91488 | I7: =H10 -> 312.79276 | J7: =I10 -> 328.68214
A8: Plus: capital expenditures | B8: $m | D8: =D10-D7+D9 -> 48.1 | E8: =E10-E7+E9 -> 52.1 | F8: =Assumptions!F39*'Income Statement'!F10 -> 56.672785 | G8: =Assumptions!G39*'Income Statement'!G10 -> 58.855194 | H8: =Assumptions!H39*'Income Statement'!H10 -> 59.785544 | I8: =Assumptions!I39*'Income Statement'!I10 -> 61.244327 | J8: =Assumptions!J39*'Income Statement'!J10 -> 61.142279
A9: Less: depreciation and amortization | B9: $m | C9: ='Income Statement'!C20 -> 30.5 | D9: ='Income Statement'!D20 -> 32.8 | E9: ='Income Statement'!E20 -> 35.4 | F9: =Assumptions!F57*F7 -> 37.41 | G9: =Assumptions!G57*G7 -> 40.203104 | H9: =Assumptions!H57*H7 -> 42.907657 | I9: =Assumptions!I57*I7 -> 45.354951 | J9: =Assumptions!J57*J7 -> 47.65891
A10: Closing net PP&E | B10: $m | C10: ='Balance Sheet'!C12 -> 226 | D10: ='Balance Sheet'!D12 -> 241.3 | E10: ='Balance Sheet'!E12 -> 258 | F10: =F7+F8-F9 -> 277.26279 | G10: =G7+G8-G9 -> 295.91488 | H10: =H7+H8-H9 -> 312.79276 | I10: =I7+I8-I9 -> 328.68214 | J10: =J7+J8-J9 -> 342.16551
A12: Working capital (days based)
A13: Accounts receivable | B13: $m | C13: ='Balance Sheet'!C8 -> 95.4 | D13: ='Balance Sheet'!D8 -> 106 | E13: ='Balance Sheet'!E8 -> 115.5 | F13: =Assumptions!F43/Days_In_Year*'Income Statement'!F10 -> 124.21432 | G13: =Assumptions!G43/Days_In_Year*'Income Statement'!G10 -> 133.09285 | H13: =Assumptions!H43/Days_In_Year*'Income Statement'!H10 -> 141.95654 | I13: =Assumptions!I43/Days_In_Year*'Income Statement'!I10 -> 148.98832 | J13: =Assumptions!J43/Days_In_Year*'Income Statement'!J10 -> 155.33032
A14: Inventory | B14: $m | C14: ='Balance Sheet'!C9 -> 92.2 | D14: ='Balance Sheet'!D9 -> 98.3 | E14: ='Balance Sheet'!E9 -> 104.9 | F14: =Assumptions!F47/Days_In_Year*'Income Statement'!F13 -> 112.33036 | G14: =Assumptions!G47/Days_In_Year*'Income Statement'!G13 -> 118.37585 | H14: =Assumptions!H47/Days_In_Year*'Income Statement'!H13 -> 125.65338 | I14: =Assumptions!I47/Days_In_Year*'Income Statement'!I13 -> 130.93615 | J14: =Assumptions!J47/Days_In_Year*'Income Statement'!J13 -> 137.84805
A15: Prepaid and other current assets | B15: $m | C15: ='Balance Sheet'!C10 -> 17.1 | D15: ='Balance Sheet'!D10 -> 18.6 | E15: ='Balance Sheet'!E10 -> 20.3 | F15: =Assumptions!F54*'Income Statement'!F10 -> 21.797225 | G15: =Assumptions!G54*'Income Statement'!G10 -> 23.355236 | H15: =Assumptions!H54*'Income Statement'!H10 -> 24.910643 | I15: =Assumptions!I54*'Income Statement'!I10 -> 26.398417 | J15: =Assumptions!J54*'Income Statement'!J10 -> 27.791945
A16: Accounts payable | B16: $m | C16: ='Balance Sheet'!C17 -> 56.3 | D16: ='Balance Sheet'!D17 -> 62.1 | E16: ='Balance Sheet'!E17 -> 67.2 | F16: =Assumptions!F56/Days_In_Year*'Income Statement'!F13 -> 71.891428 | G16: =Assumptions!G56/Days_In_Year*'Income Statement'!G13 -> 76.784337 | H16: =Assumptions!H56/Days_In_Year*'Income Statement'!H13 -> 81.504895 | I16: =Assumptions!I56/Days_In_Year*'Income Statement'!I13 -> 86.095001 | J16: =Assumptions!J56/Days_In_Year*'Income Statement'!J13 -> 90.639812
A17: Accrued liabilities | B17: $m | C17: ='Balance Sheet'!C18 -> 37.6 | D17: ='Balance Sheet'!D18 -> 40.9 | E17: ='Balance Sheet'!E18 -> 44.6 | F17: =Assumptions!F55*'Income Statement'!F10 -> 47.953895 | G17: =Assumptions!G55*'Income Statement'!G10 -> 51.381519 | H17: =Assumptions!H55*'Income Statement'!H10 -> 54.803416 | I17: =Assumptions!I55*'Income Statement'!I10 -> 58.076517 | J17: =Assumptions!J55*'Income Statement'!J10 -> 61.142279
A18: Net working capital | B18: $m | C18: =C13+C14+C15-C16-C17 -> 110.8 | D18: =D13+D14+D15-D16-D17 -> 119.9 | E18: =E13+E14+E15-E16-E17 -> 128.9 | F18: =F13+F14+F15-F16-F17 -> 138.49658 | G18: =G13+G14+G15-G16-G17 -> 146.65808 | H18: =H13+H14+H15-H16-H17 -> 156.21226 | I18: =I13+I14+I15-I16-I17 -> 162.15137 | J18: =J13+J14+J15-J16-J17 -> 169.18822
A19: Increase / (decrease) in net working capital | B19: $m | D19: =D18-C18 -> 9.1 | E19: =E18-D18 -> 9 | F19: =F18-E18 -> 9.5965817 | G19: =G18-F18 -> 8.1615014 | H19: =H18-G18 -> 9.5541733 | I19: =I18-H18 -> 5.9391146 | J19: =J18-I18 -> 7.0368537
A21: Term loan
A22: Opening balance | B22: $m | D22: =C24 -> 210 | E22: =D24 -> 195 | F22: =E24 -> 180 | G22: =F24 -> 155 | H22: =G24 -> 130 | I22: =H24 -> 105 | J22: =I24 -> 80
A23: Less: mandatory amortization | B23: $m | D23: =D22-D24 -> 15 | E23: =E22-E24 -> 15 | F23: =MIN(F22,Assumptions!F64) -> 25 | G23: =MIN(G22,Assumptions!G64) -> 25 | H23: =MIN(H22,Assumptions!H64) -> 25 | I23: =MIN(I22,Assumptions!I64) -> 25 | J23: =MIN(J22,Assumptions!J64) -> 25
A24: Closing balance | B24: $m | C24: ='Balance Sheet'!C20 -> 210 | D24: ='Balance Sheet'!D20 -> 195 | E24: ='Balance Sheet'!E20 -> 180 | F24: =F22-F23 -> 155 | G24: =G22-G23 -> 130 | H24: =H22-H23 -> 105 | I24: =I22-I23 -> 80 | J24: =J22-J23 -> 55
A26: Cash available before revolver
A27: Opening cash | B27: $m | F27: ='Balance Sheet'!E7 -> 88.6 | G27: ='Balance Sheet'!F7 -> 68.193502 | H27: ='Balance Sheet'!G7 -> 60 | I27: ='Balance Sheet'!H7 -> 60 | J27: ='Balance Sheet'!I7 -> 60
A28: Plus: cash flow from operations | B28: $m | F28: ='Cash Flow'!F14 -> 111.31752 | G28: ='Cash Flow'!G14 -> 124.94259 | H28: ='Cash Flow'!H14 -> 136.76467 | I28: ='Cash Flow'!I14 -> 152.8488 | J28: ='Cash Flow'!J14 -> 162.59315
A29: Plus: cash flow from investing | B29: $m | F29: ='Cash Flow'!F18 -> -56.672785 | G29: ='Cash Flow'!G18 -> -58.855194 | H29: ='Cash Flow'!H18 -> -59.785544 | I29: ='Cash Flow'!I18 -> -61.244327 | J29: ='Cash Flow'!J18 -> -61.142279
A30: Less: term loan amortization | B30: $m | F30: =-F23 -> -25 | G30: =-G23 -> -25 | H30: =-H23 -> -25 | I30: =-I23 -> -25 | J30: =-J23 -> -25
A31: Plus: stock issuance | B31: $m | F31: =F61 -> 5 | G31: =G61 -> 5 | H31: =H61 -> 5 | I31: =I61 -> 5 | J31: =J61 -> 5
A32: Less: dividends | B32: $m | F32: =-F56 -> -25.05123 | G32: =-G56 -> -27.870295 | H32: =-H56 -> -31.023355 | I32: =-I56 -> -34.029889 | J32: =-J56 -> -36.591328
A33: Less: share buybacks | B33: $m | F33: =-F64 -> -30 | G33: =-G64 -> -30 | H33: =-H64 -> -30 | I33: =-I64 -> -35 | J33: =-J64 -> -35
A34: Cash before revolver | B34: $m | F34: =SUM(F27:F33) -> 68.193502 | G34: =SUM(G27:G33) -> 56.410599 | H34: =SUM(H27:H33) -> 55.955767 | I34: =SUM(I27:I33) -> 62.574584 | J34: =SUM(J27:J33) -> 69.859543
A35: Minimum cash balance | B35: $m | F35: =Min_Cash -> 60 | G35: =Min_Cash -> 60 | H35: =Min_Cash -> 60 | I35: =Min_Cash -> 60 | J35: =Min_Cash -> 60
A36: Surplus / (shortfall) versus minimum | B36: $m | F36: =F34-F35 -> 8.1935022 | G36: =G34-G35 -> -3.5894008 | H36: =H34-H35 -> -4.0442332 | I36: =I34-I35 -> 2.5745837 | J36: =J34-J35 -> 9.8595428
A38: Revolving credit facility
A39: Opening balance | B39: $m | D39: =C41 -> 15 | E39: =D41 -> 0 | F39: =E41 -> 0 | G39: =F41 -> 0 | H39: =G41 -> 3.5894008 | I39: =H41 -> 7.6336341 | J39: =I41 -> 5.0590503
A40: Draw / (repayment) | B40: $m | D40: =D41-D39 -> -15 | E40: =E41-E39 -> 0 | F40: =MAX(-F39,MIN(F35-F34,Revolver_Limit-F39)) -> 0 | G40: =MAX(-G39,MIN(G35-G34,Revolver_Limit-G39)) -> 3.5894008 | H40: =MAX(-H39,MIN(H35-H34,Revolver_Limit-H39)) -> 4.0442332 | I40: =MAX(-I39,MIN(I35-I34,Revolver_Limit-I39)) -> -2.5745837 | J40: =MAX(-J39,MIN(J35-J34,Revolver_Limit-J39)) -> -5.0590503
A41: Closing balance | B41: $m | C41: ='Balance Sheet'!C19 -> 15 | D41: ='Balance Sheet'!D19 -> 0 | E41: ='Balance Sheet'!E19 -> 0 | F41: =F39+F40 -> 0 | G41: =G39+G40 -> 3.5894008 | H41: =H39+H40 -> 7.6336341 | I41: =I39+I40 -> 5.0590503 | J41: =J39+J40 -> 0
A42: Cash after revolver | B42: $m | F42: =F34+F40 -> 68.193502 | G42: =G34+G40 -> 60 | H42: =H34+H40 -> 60 | I42: =I34+I40 -> 60 | J42: =J34+J40 -> 64.800492
A44: Total debt | B44: $m | C44: =C24+C41 -> 225 | D44: =D24+D41 -> 195 | E44: =E24+E41 -> 180 | F44: =F24+F41 -> 155 | G44: =G24+G41 -> 133.5894 | H44: =H24+H41 -> 112.63363 | I44: =I24+I41 -> 85.05905 | J44: =J24+J41 -> 55
A45: Net debt | B45: $m | C45: =C44-'Balance Sheet'!C7 -> 106.8 | D45: =D44-'Balance Sheet'!D7 -> 102.4 | E45: =E44-'Balance Sheet'!E7 -> 91.4 | F45: =F44-'Balance Sheet'!F7 -> 86.806498 | G45: =G44-'Balance Sheet'!G7 -> 73.589401 | H45: =H44-'Balance Sheet'!H7 -> 52.633634 | I45: =I44-'Balance Sheet'!I7 -> 25.05905 | J45: =J44-'Balance Sheet'!J7 -> -9.8004925
...

Sheet Checks
A1: Northwind Components Inc. (fictional) | Model integrity checks
A2: Every row must be zero; status column must read TRUE. $ in millions except per share data; fiscal year ends December 31.
A3: ="Scenario: "&Scenario -> Scenario: Base
C4: Actual | F4: Forecast
A5: ($ in millions) | B5: Unit | C5: =Assumptions!C$5 -> 2023 | D5: =Assumptions!D$5 -> 2024 | E5: =Assumptions!E$5 -> 2025 | F5: =Assumptions!F$5 -> 2026 | G5: =Assumptions!G$5 -> 2027 | H5: =Assumptions!H$5 -> 2028 | I5: =Assumptions!I$5 -> 2029 | J5: =Assumptions!J$5 -> 2030 | K5: Pass?
A6: Integrity checks (each row should be zero in every year)
A7: Balance sheet balances (assets less liabilities and equity) | B7: $m | C7: =ROUND('Balance Sheet'!C14-'Balance Sheet'!C29,6) -> 0 | D7: =ROUND('Balance Sheet'!D14-'Balance Sheet'!D29,6) -> 0 | E7: =ROUND('Balance Sheet'!E14-'Balance Sheet'!E29,6) -> 0 | F7: =ROUND('Balance Sheet'!F14-'Balance Sheet'!F29,6) -> 0 | G7: =ROUND('Balance Sheet'!G14-'Balance Sheet'!G29,6) -> 0 | H7: =ROUND('Balance Sheet'!H14-'Balance Sheet'!H29,6) -> 0 | I7: =ROUND('Balance Sheet'!I14-'Balance Sheet'!I29,6) -> 0 | J7: =ROUND('Balance Sheet'!J14-'Balance Sheet'!J29,6) -> 0 | K7: =SUMPRODUCT(ABS(C7:J7))<Tolerance -> TRUE
A8: Balance sheet cash ties to cash flow statement ending cash | B8: $m | F8: =ROUND('Balance Sheet'!F7-'Cash Flow'!F30,6) -> 0 | G8: =ROUND('Balance Sheet'!G7-'Cash Flow'!G30,6) -> 0 | H8: =ROUND('Balance Sheet'!H7-'Cash Flow'!H30,6) -> 0 | I8: =ROUND('Balance Sheet'!I7-'Cash Flow'!I30,6) -> 0 | J8: =ROUND('Balance Sheet'!J7-'Cash Flow'!J30,6) -> 0 | K8: =SUMPRODUCT(ABS(C8:J8))<Tolerance -> TRUE
A9: Cash flow ending cash ties to debt schedule cash after revolver | B9: $m | F9: =ROUND('Cash Flow'!F30-Schedules!F42,6) -> 0 | G9: =ROUND('Cash Flow'!G30-Schedules!G42,6) -> 0 | H9: =ROUND('Cash Flow'!H30-Schedules!H42,6) -> 0 | I9: =ROUND('Cash Flow'!I30-Schedules!I42,6) -> 0 | J9: =ROUND('Cash Flow'!J30-Schedules!J42,6) -> 0 | K9: =SUMPRODUCT(ABS(C9:J9))<Tolerance -> TRUE
A10: Retained earnings roll-forward (prior + net income - dividends) | B10: $m | F10: =ROUND('Balance Sheet'!F26-('Balance Sheet'!E26+'Income Statement'!F27+'Cash Flow'!F24),6) -> 0 | G10: =ROUND('Balance Sheet'!G26-('Balance Sheet'!F26+'Income Statement'!G27+'Cash Flow'!G24),6) -> 0 | H10: =ROUND('Balance Sheet'!H26-('Balance Sheet'!G26+'Income Statement'!H27+'Cash Flow'!H24),6) -> 0 | I10: =ROUND('Balance Sheet'!I26-('Balance Sheet'!H26+'Income Statement'!I27+'Cash Flow'!I24),6) -> 0 | J10: =ROUND('Balance Sheet'!J26-('Balance Sheet'!I26+'Income Statement'!J27+'Cash Flow'!J24),6) -> 0 | K10: =SUMPRODUCT(ABS(C10:J10))<Tolerance -> TRUE
A11: Debt roll-forward (prior debt + financing flows) | B11: $m | F11: =ROUND(('Balance Sheet'!F20+'Balance Sheet'!F19)-('Balance Sheet'!E20+'Balance Sheet'!E19+'Cash Flow'!F21+'Cash Flow'!F22),6) -> 0 | G11: =ROUND(('Balance Sheet'!G20+'Balance Sheet'!G19)-('Balance Sheet'!F20+'Balance Sheet'!F19+'Cash Flow'!G21+'Cash Flow'!G22),6) -> 0 | H11: =ROUND(('Balance Sheet'!H20+'Balance Sheet'!H19)-('Balance Sheet'!G20+'Balance Sheet'!G19+'Cash Flow'!H21+'Cash Flow'!H22),6) -> 0 | I11: =ROUND(('Balance Sheet'!I20+'Balance Sheet'!I19)-('Balance Sheet'!H20+'Balance Sheet'!H19+'Cash Flow'!I21+'Cash Flow'!I22),6) -> 0 | J11: =ROUND(('Balance Sheet'!J20+'Balance Sheet'!J19)-('Balance Sheet'!I20+'Balance Sheet'!I19+'Cash Flow'!J21+'Cash Flow'!J22),6) -> 0 | K11: =SUMPRODUCT(ABS(C11:J11))<Tolerance -> TRUE
A12: PP&E roll-forward (prior + capex - D&A) | B12: $m | F12: =ROUND('Balance Sheet'!F12-('Balance Sheet'!E12-'Cash Flow'!F17-'Income Statement'!F20),6) -> 0 | G12: =ROUND('Balance Sheet'!G12-('Balance Sheet'!F12-'Cash Flow'!G17-'Income Statement'!G20),6) -> 0 | H12: =ROUND('Balance Sheet'!H12-('Balance Sheet'!G12-'Cash Flow'!H17-'Income Statement'!H20),6) -> 0 | I12: =ROUND('Balance Sheet'!I12-('Balance Sheet'!H12-'Cash Flow'!I17-'Income Statement'!I20),6) -> 0 | J12: =ROUND('Balance Sheet'!J12-('Balance Sheet'!I12-'Cash Flow'!J17-'Income Statement'!J20),6) -> 0 | K12: =SUMPRODUCT(ABS(C12:J12))<Tolerance -> TRUE
A13: Total equity roll-forward (net income, issuance, dividends, buybacks) | B13: $m | F13: =ROUND('Balance Sheet'!F28-('Balance Sheet'!E28+'Income Statement'!F27+'Cash Flow'!F23+'Cash Flow'!F24+'Cash Flow'!F25),6) -> 0 | G13: =ROUND('Balance Sheet'!G28-('Balance Sheet'!F28+'Income Statement'!G27+'Cash Flow'!G23+'Cash Flow'!G24+'Cash Flow'!G25),6) -> 0 | H13: =ROUND('Balance Sheet'!H28-('Balance Sheet'!G28+'Income Statement'!H27+'Cash Flow'!H23+'Cash Flow'!H24+'Cash Flow'!H25),6) -> 0 | I13: =ROUND('Balance Sheet'!I28-('Balance Sheet'!H28+'Income Statement'!I27+'Cash Flow'!I23+'Cash Flow'!I24+'Cash Flow'!I25),6) -> 0 | J13: =ROUND('Balance Sheet'!J28-('Balance Sheet'!I28+'Income Statement'!J27+'Cash Flow'!J23+'Cash Flow'!J24+'Cash Flow'!J25),6) -> 0 | K13: =SUMPRODUCT(ABS(C13:J13))<Tolerance -> TRUE
A14: Cash flow working capital lines tie to schedule change in NWC | B14: $m | F14: =ROUND(SUM('Cash Flow'!F9:F13)+Schedules!F19,6) -> 0 | G14: =ROUND(SUM('Cash Flow'!G9:G13)+Schedules!G19,6) -> 0 | H14: =ROUND(SUM('Cash Flow'!H9:H13)+Schedules!H19,6) -> 0 | I14: =ROUND(SUM('Cash Flow'!I9:I13)+Schedules!I19,6) -> 0 | J14: =ROUND(SUM('Cash Flow'!J9:J13)+Schedules!J19,6) -> 0 | K14: =SUMPRODUCT(ABS(C14:J14))<Tolerance -> TRUE
A15: Minimum cash maintained (shortfall) | B15: $m | F15: =ROUND(MAX(0,Min_Cash-'Balance Sheet'!F7),6) -> 0 | G15: =ROUND(MAX(0,Min_Cash-'Balance Sheet'!G7),6) -> 0 | H15: =ROUND(MAX(0,Min_Cash-'Balance Sheet'!H7),6) -> 0 | I15: =ROUND(MAX(0,Min_Cash-'Balance Sheet'!I7),6) -> 0 | J15: =ROUND(MAX(0,Min_Cash-'Balance Sheet'!J7),6) -> 0 | K15: =SUMPRODUCT(ABS(C15:J15))<Tolerance -> TRUE
A16: Revolver within commitment (excess) | B16: $m | F16: =ROUND(MAX(0,'Balance Sheet'!F19-Revolver_Limit),6) -> 0 | G16: =ROUND(MAX(0,'Balance Sheet'!G19-Revolver_Limit),6) -> 0 | H16: =ROUND(MAX(0,'Balance Sheet'!H19-Revolver_Limit),6) -> 0 | I16: =ROUND(MAX(0,'Balance Sheet'!I19-Revolver_Limit),6) -> 0 | J16: =ROUND(MAX(0,'Balance Sheet'!J19-Revolver_Limit),6) -> 0 | K16: =SUMPRODUCT(ABS(C16:J16))<Tolerance -> TRUE
A17: No negative debt balances | B17: $m | C17: =ROUND(MAX(0,-'Balance Sheet'!C19)+MAX(0,-'Balance Sheet'!C20),6) -> 0 | D17: =ROUND(MAX(0,-'Balance Sheet'!D19)+MAX(0,-'Balance Sheet'!D20),6) -> 0 | E17: =ROUND(MAX(0,-'Balance Sheet'!E19)+MAX(0,-'Balance Sheet'!E20),6) -> 0 | F17: =ROUND(MAX(0,-'Balance Sheet'!F19)+MAX(0,-'Balance Sheet'!F20),6) -> 0 | G17: =ROUND(MAX(0,-'Balance Sheet'!G19)+MAX(0,-'Balance Sheet'!G20),6) -> 0 | H17: =ROUND(MAX(0,-'Balance Sheet'!H19)+MAX(0,-'Balance Sheet'!H20),6) -> 0 | I17: =ROUND(MAX(0,-'Balance Sheet'!I19)+MAX(0,-'Balance Sheet'!I20),6) -> 0 | J17: =ROUND(MAX(0,-'Balance Sheet'!J19)+MAX(0,-'Balance Sheet'!J20),6) -> 0 | K17: =SUMPRODUCT(ABS(C17:J17))<Tolerance -> TRUE
A19: ALL CHECKS PASS | C19: =AND(K7:K17) -> TRUE
A20: Tolerance is set on the Assumptions sheet (named range Tolerance).

Sheet Sensitivity
A1: Northwind Components Inc. (fictional) | Sensitivity analysis
A2: FY2030E EBITDA and free cash flow. $ in millions. Scenario at build time: Base.
A4: PYTHON-GENERATED TABLE: static values, not Excel formulas. Each cell is a full re-run of the three-statement model (three_statement.sensitivity) with every segment's growth and the gross margin shifted in every forecast year. It does NOT respond to the scenario dropdown; it reflects the Base scenario selected when the file was built. Rebuild with 'three-statement build --scenario <name>' to refresh.
A6: FY2030E EBITDA ($m)
C7: Revenue growth shift (pp per year, every segment)
B8: Margin shift | C8: -2 | D8: -1 | E8: 0 | F8: 1 | G8: 2
B9: -2 | C9: 174.93294 | D9: 183.46186 | E9: 192.32026 | F9: 201.51761 | G9: 211.06355
B10: -1 | C10: 185.04468 | D10: 194.06659 | E10: 203.43704 | F10: 213.16603 | G10: 223.26375
A11: Gross margin shift (pp, every forecast year) | B11: 0 | C11: 195.15641 | D11: 204.67132 | E11: 214.55382 | F11: 224.81445 | G11: 235.46396
B12: 1 | C12: 205.26814 | D12: 215.27605 | E12: 225.67059 | F12: 236.46286 | G12: 247.66416
B13: 2 | C13: 215.37987 | D13: 225.88078 | E13: 236.78737 | F13: 248.11128 | G13: 259.86437
A16: FY2030E free cash flow ($m)
C17: Revenue growth shift (pp per year, every segment)
B18: Margin shift | C18: -2 | D18: -1 | E18: 0 | F18: 1 | G18: 2
B19: -2 | C19: 78.318679 | D19: 80.30087 | E19: 82.298989 | F19: 84.311889 | G19: 86.338336
B20: -1 | C20: 87.066161 | D20: 89.455688 | E20: 91.876575 | F20: 94.328082 | G20: 96.809426
A21: Gross margin shift (pp, every forecast year) | B21: 0 | C21: 95.813493 | D21: 98.608878 | E21: 101.45087 | F21: 104.33932 | G21: 107.2739
B22: 1 | C22: 103.82798 | D22: 107.08798 | E22: 110.41315 | F22: 113.80373 | G22: 117.25989
B23: 2 | C23: 111.81562 | D23: 115.46267 | E23: 119.18994 | F23: 122.99808 | G23: 126.88771
A25: Highlighted cell: unshifted model for the scenario above (matches the Summary sheet when that scenario is selected).
